<sdf version='1.7'>
  <model name='robomaster_s1'>
    <link name='base_link'>
      <inertial>
        <pose>-0.00582 -0.000128 0.06488 0 -0 0</pose>
        <mass>1.972</mass>
        <inertia>
          <ixx>0.0226634</ixx>
          <ixy>-4.92998e-07</ixy>
          <ixz>-8.45425e-06</ixz>
          <iyy>0.013324</iyy>
          <iyz>1.25334e-06</iyz>
          <izz>0.0257901</izz>
        </inertia>
      </inertial>
      <collision name='base_link_fixed_joint_lump__base_collision_collision'>
        <pose>-0.005879 -0.000113 0.064081 0 -0 0</pose>
        <geometry>
          <mesh>
            <scale>1 1 1</scale>
            <uri>model://robomaster_description/meshes/base_collision.dae</uri>
          </mesh>
        </geometry>
      </collision>
      <collision name='base_link_fixed_joint_lump__gimbal_base_collision_collision_1'>
        <pose>-0.00316 -0.00092 0.11557 0 -0 0</pose>
        <geometry>
          <mesh>
            <scale>1 1 1</scale>
            <uri>model://robomaster_description/meshes/gimbal_base_collision.dae</uri>
          </mesh>
        </geometry>
      </collision>
      <visual name='base_link_fixed_joint_lump__armor_visual'>
        <pose>-0.006455 -0.078141 0.063938 0 -0 0</pose>
        <geometry>
          <mesh>
            <scale>1 1 1</scale>
            <uri>model://robomaster_description/meshes/armor.dae</uri>
          </mesh>
        </geometry>
      </visual>
      <visual name='base_link_fixed_joint_lump__battery_visual_1'>
        <pose>-0.130336 -0.00187 0.052068 0 -0 0</pose>
        <geometry>
          <mesh>
            <scale>1 1 1</scale>
            <uri>model://robomaster_description/meshes/battery.dae</uri>
          </mesh>
        </geometry>
      </visual>
      <visual name='base_link_fixed_joint_lump__battery_pin_left_visual_2'>
        <pose>-0.115891 0.066115 0.087174 0 -0 0</pose>
        <geometry>
          <mesh>
            <scale>1 1 1</scale>
            <uri>model://robomaster_description/meshes/battery_pin_left.dae</uri>
          </mesh>
        </geometry>
      </visual>
      <visual name='base_link_fixed_joint_lump__battery_pin_right_visual_3'>
        <pose>-0.115891 -0.065884 0.087174 0 -0 0</pose>
        <geometry>
          <mesh>
            <scale>1 1 1</scale>
            <uri>model://robomaster_description/meshes/battery_pin_right.dae</uri>
          </mesh>
        </geometry>
      </visual>
      <visual name='base_link_fixed_joint_lump__chassis_visual_4'>
        <pose>-0.005904 0.000415 0.087446 0 -0 0</pose>
        <geometry>
          <mesh>
            <scale>1 1 1</scale>
            <uri>model://robomaster_description/meshes/chassis.dae</uri>
          </mesh>
        </geometry>
      </visual>
      <visual name='base_link_fixed_joint_lump__controller_visual_5'>
        <pose>-0.114229 -0.000672 0.087325 0 -0 0</pose>
        <geometry>
          <mesh>
            <scale>1 1 1</scale>
            <uri>model://robomaster_description/meshes/controller.dae</uri>
          </mesh>
        </geometry>
      </visual>
      <visual name='base_link_fixed_joint_lump__controller_cover_visual_6'>
        <pose>-0.078776 -0.002522 0.106733 0 -0 0</pose>
        <geometry>
          <mesh>
            <scale>1 1 1</scale>
            <uri>model://robomaster_description/meshes/controller_cover.dae</uri>
          </mesh>
        </geometry>
      </visual>
      <visual name='base_link_fixed_joint_lump__front_hit_sensor_visual_7'>
        <pose>0.156999 -0.000428 0.077936 0 -0 0</pose>
        <geometry>
          <mesh>
            <scale>1 1 1</scale>
            <uri>model://robomaster_description/meshes/hit_sensor.dae</uri>
          </mesh>
        </geometry>
      </visual>
      <visual name='base_link_fixed_joint_lump__front_led_visual_8'>
        <pose>0.165741 -0.001712 0.077974 0 -0 0</pose>
        <geometry>
          <mesh>
            <scale>1 1 1</scale>
            <uri>model://robomaster_description/meshes/led.dae</uri>
          </mesh>
        </geometry>
      </visual>
      <visual name='base_link_fixed_joint_lump__left_hit_sensor_visual_9'>
        <pose>-0.002441 0.088693 0.064484 0 -0 1.5708</pose>
        <geometry>
          <mesh>
            <scale>1 1 1</scale>
            <uri>model://robomaster_description/meshes/hit_sensor.dae</uri>
          </mesh>
        </geometry>
      </visual>
      <visual name='base_link_fixed_joint_lump__left_led_visual_10'>
        <pose>-0.001157 0.097436 0.064522 0 -0 1.5708</pose>
        <geometry>
          <mesh>
            <scale>1 1 1</scale>
            <uri>model://robomaster_description/meshes/led.dae</uri>
          </mesh>
        </geometry>
      </visual>
      <visual name='base_link_fixed_joint_lump__rear_hit_sensor_visual_11'>
        <pose>-0.158183 -0.002786 0.065017 0 -0 3.14159</pose>
        <geometry>
          <mesh>
            <scale>1 1 1</scale>
            <uri>model://robomaster_description/meshes/hit_sensor.dae</uri>
          </mesh>
        </geometry>
      </visual>
      <visual name='base_link_fixed_joint_lump__rear_led_visual_12'>
        <pose>-0.166926 -0.001502 0.065054 0 -0 3.14159</pose>
        <geometry>
          <mesh>
            <scale>1 1 1</scale>
            <uri>model://robomaster_description/meshes/led.dae</uri>
          </mesh>
        </geometry>
      </visual>
      <visual name='base_link_fixed_joint_lump__right_hit_sensor_visual_13'>
        <pose>-0.002441 -0.088693 0.064484 0 0 -1.5708</pose>
        <geometry>
          <mesh>
            <scale>1 1 1</scale>
            <uri>model://robomaster_description/meshes/hit_sensor.dae</uri>
          </mesh>
        </geometry>
      </visual>
      <visual name='base_link_fixed_joint_lump__right_led_visual_14'>
        <pose>-0.003725 -0.097436 0.064522 0 0 -1.5708</pose>
        <geometry>
          <mesh>
            <scale>1 1 1</scale>
            <uri>model://robomaster_description/meshes/led.dae</uri>
          </mesh>
        </geometry>
      </visual>
      <visual name='base_link_fixed_joint_lump__gimbal_base_visual_15'>
        <pose>-0.002 0 0.118 0 -0 0</pose>
        <geometry>
          <mesh>
            <scale>1 1 1</scale>
            <uri>model://robomaster_description/meshes/gimbal_base.dae</uri>
          </mesh>
        </geometry>
      </visual>
    </link>
    <joint name='front_left_wheel_joint' type='revolute'>
      <pose relative_to='base_link'>0.1 0.1 0.05 0 -0 0</pose>
      <parent>base_link</parent>
      <child>front_left_wheel_link</child>
      <axis>
        <xyz>0 1 0</xyz>
        <limit>
          <effort>0</effort>
          <velocity>0</velocity>
          <lower>-1e+16</lower>
          <upper>1e+16</upper>
        </limit>
        <dynamics>
          <spring_reference>0</spring_reference>
          <spring_stiffness>0</spring_stiffness>
        </dynamics>
      </axis>
    </joint>
    <link name='front_left_wheel_link'>
      <pose relative_to='front_left_wheel_joint'>0 0 0 0 -0 0</pose>
      <inertial>
        <pose>-0.00021 5.3e-05 -0.000415 0 -0 0</pose>
        <mass>0.162</mass>
        <inertia>
          <ixx>0.0002</ixx>
          <ixy>0</ixy>
          <ixz>0</ixz>
          <iyy>0.00012</iyy>
          <iyz>0</iyz>
          <izz>0.00012</izz>
        </inertia>
      </inertial>
      <collision name='front_left_wheel_link_fixed_joint_lump__front_left_wheel_collision'>
        <pose>0 0 0 1.5708 -0 0</pose>
        <geometry>
          <cylinder>
            <length>0.042</length>
            <radius>0.05</radius>
          </cylinder>
        </geometry>
      </collision>
      <visual name='front_left_wheel_link_fixed_joint_lump__front_left_wheel_bolt_visual'>
        <pose>0 0.0145 0 1.5708 -0 0</pose>
        <geometry>
          <cylinder>
            <length>0.001</length>
            <radius>0.007</radius>
          </cylinder>
        </geometry>
      </visual>
      <visual name='front_left_wheel_link_fixed_joint_lump__front_left_wheel_visual_1'>
        <pose>0 0 0 0 -0 0</pose>
        <geometry>
          <mesh>
            <scale>1 1 1</scale>
            <uri>model://robomaster_description/meshes/wheel.dae</uri>
          </mesh>
        </geometry>
      </visual>
    </link>
    <joint name='front_right_wheel_joint' type='revolute'>
      <pose relative_to='base_link'>0.1 -0.1 0.05 0 -0 0</pose>
      <parent>base_link</parent>
      <child>front_right_wheel_link</child>
      <axis>
        <xyz>0 1 0</xyz>
        <limit>
          <effort>0</effort>
          <velocity>0</velocity>
          <lower>-1e+16</lower>
          <upper>1e+16</upper>
        </limit>
        <dynamics>
          <spring_reference>0</spring_reference>
          <spring_stiffness>0</spring_stiffness>
        </dynamics>
      </axis>
    </joint>
    <link name='front_right_wheel_link'>
      <pose relative_to='front_right_wheel_joint'>0 0 0 0 -0 0</pose>
      <inertial>
        <pose>-0.00021 5.3e-05 -0.000415 0 -0 0</pose>
        <mass>0.162</mass>
        <inertia>
          <ixx>0.0002</ixx>
          <ixy>0</ixy>
          <ixz>0</ixz>
          <iyy>0.00012</iyy>
          <iyz>0</iyz>
          <izz>0.00012</izz>
        </inertia>
      </inertial>
      <collision name='front_right_wheel_link_fixed_joint_lump__front_right_wheel_collision'>
        <pose>0 0 0 1.5708 -0 0</pose>
        <geometry>
          <cylinder>
            <length>0.042</length>
            <radius>0.05</radius>
          </cylinder>
        </geometry>
      </collision>
      <visual name='front_right_wheel_link_fixed_joint_lump__front_right_wheel_bolt_visual'>
        <pose>0 -0.0145 0 1.5708 -0 0</pose>
        <geometry>
          <cylinder>
            <length>0.001</length>
            <radius>0.007</radius>
          </cylinder>
        </geometry>
      </visual>
      <visual name='front_right_wheel_link_fixed_joint_lump__front_right_wheel_visual_1'>
        <pose>0 0 0 0 -0 0</pose>
        <geometry>
          <mesh>
            <scale>1 -1 1</scale>
            <uri>model://robomaster_description/meshes/wheel.dae</uri>
          </mesh>
        </geometry>
      </visual>
    </link>
    <joint name='rear_left_wheel_joint' type='revolute'>
      <pose relative_to='base_link'>-0.1 0.1 0.05 0 -0 0</pose>
      <parent>base_link</parent>
      <child>rear_left_wheel_link</child>
      <axis>
        <xyz>0 1 0</xyz>
        <limit>
          <effort>0</effort>
          <velocity>0</velocity>
          <lower>-1e+16</lower>
          <upper>1e+16</upper>
        </limit>
        <dynamics>
          <spring_reference>0</spring_reference>
          <spring_stiffness>0</spring_stiffness>
        </dynamics>
      </axis>
    </joint>
    <link name='rear_left_wheel_link'>
      <pose relative_to='rear_left_wheel_joint'>0 0 0 0 -0 0</pose>
      <inertial>
        <pose>-0.00021 5.3e-05 -0.000415 0 -0 0</pose>
        <mass>0.162</mass>
        <inertia>
          <ixx>0.0002</ixx>
          <ixy>0</ixy>
          <ixz>0</ixz>
          <iyy>0.00012</iyy>
          <iyz>0</iyz>
          <izz>0.00012</izz>
        </inertia>
      </inertial>
      <collision name='rear_left_wheel_link_fixed_joint_lump__rear_left_wheel_collision'>
        <pose>0 0 0 1.5708 -0 0</pose>
        <geometry>
          <cylinder>
            <length>0.042</length>
            <radius>0.05</radius>
          </cylinder>
        </geometry>
      </collision>
      <visual name='rear_left_wheel_link_fixed_joint_lump__rear_left_wheel_bolt_visual'>
        <pose>0 0.0145 0 1.5708 -0 0</pose>
        <geometry>
          <cylinder>
            <length>0.001</length>
            <radius>0.007</radius>
          </cylinder>
        </geometry>
      </visual>
      <visual name='rear_left_wheel_link_fixed_joint_lump__rear_left_wheel_visual_1'>
        <pose>0 0 0 0 -0 0</pose>
        <geometry>
          <mesh>
            <scale>1 -1 1</scale>
            <uri>model://robomaster_description/meshes/wheel.dae</uri>
          </mesh>
        </geometry>
      </visual>
    </link>
    <joint name='rear_right_wheel_joint' type='revolute'>
      <pose relative_to='base_link'>-0.1 -0.1 0.05 0 -0 0</pose>
      <parent>base_link</parent>
      <child>rear_right_wheel_link</child>
      <axis>
        <xyz>0 1 0</xyz>
        <limit>
          <effort>0</effort>
          <velocity>0</velocity>
          <lower>-1e+16</lower>
          <upper>1e+16</upper>
        </limit>
        <dynamics>
          <spring_reference>0</spring_reference>
          <spring_stiffness>0</spring_stiffness>
        </dynamics>
      </axis>
    </joint>
    <link name='rear_right_wheel_link'>
      <pose relative_to='rear_right_wheel_joint'>0 0 0 0 -0 0</pose>
      <inertial>
        <pose>-0.00021 5.3e-05 -0.000415 0 -0 0</pose>
        <mass>0.162</mass>
        <inertia>
          <ixx>0.0002</ixx>
          <ixy>0</ixy>
          <ixz>0</ixz>
          <iyy>0.00012</iyy>
          <iyz>0</iyz>
          <izz>0.00012</izz>
        </inertia>
      </inertial>
      <collision name='rear_right_wheel_link_fixed_joint_lump__rear_right_wheel_collision'>
        <pose>0 0 0 1.5708 -0 0</pose>
        <geometry>
          <cylinder>
            <length>0.042</length>
            <radius>0.05</radius>
          </cylinder>
        </geometry>
      </collision>
      <visual name='rear_right_wheel_link_fixed_joint_lump__rear_right_wheel_bolt_visual'>
        <pose>0 -0.0145 0 1.5708 -0 0</pose>
        <geometry>
          <cylinder>
            <length>0.001</length>
            <radius>0.007</radius>
          </cylinder>
        </geometry>
      </visual>
      <visual name='rear_right_wheel_link_fixed_joint_lump__rear_right_wheel_visual_1'>
        <pose>0 0 0 0 -0 0</pose>
        <geometry>
          <mesh>
            <scale>1 1 1</scale>
            <uri>model://robomaster_description/meshes/wheel.dae</uri>
          </mesh>
        </geometry>
      </visual>
    </link>
    <joint name='gimbal_joint' type='revolute'>
      <pose relative_to='base_link'>-0.002 0 0.118 0 -0 0</pose>
      <parent>base_link</parent>
      <child>gimbal_link</child>
      <axis>
        <xyz>0 0 1</xyz>
        <limit>
          <lower>-4.363</lower>
          <upper>4.363</upper>
          <effort>0</effort>
          <velocity>0</velocity>
        </limit>
        <dynamics>
          <spring_reference>0</spring_reference>
          <spring_stiffness>0</spring_stiffness>
        </dynamics>
      </axis>
    </joint>
    <link name='gimbal_link'>
      <pose relative_to='gimbal_joint'>0 0 0 0 -0 0</pose>
      <inertial>
        <pose>-0.01647 -0.05644 0.05429 0 -0 0</pose>
        <mass>0.4</mass>
        <inertia>
          <ixx>0.00262</ixx>
          <ixy>-0.00029</ixy>
          <ixz>-5e-05</ixz>
          <iyy>0.00098</iyy>
          <iyz>-6e-05</iyz>
          <izz>0.00221</izz>
        </inertia>
      </inertial>
      <collision name='gimbal_link_fixed_joint_lump__gimbal_collision_collision'>
        <pose>-0.01647 -0.05644 0.05429 0 -0 0</pose>
        <geometry>
          <mesh>
            <scale>1 1 1</scale>
            <uri>model://robomaster_description/meshes/gimbal_collision.dae</uri>
          </mesh>
        </geometry>
      </collision>
      <visual name='gimbal_link_fixed_joint_lump__gimbal_visual'>
        <pose>-2e-05 -0.001 0.03369 0 -0 0</pose>
        <geometry>
          <mesh>
            <scale>1 1 1</scale>
            <uri>model://robomaster_description/meshes/gimbal.dae</uri>
          </mesh>
        </geometry>
      </visual>
      <visual name='gimbal_link_fixed_joint_lump__gimbal_left_armor_visual_1'>
        <pose>-0.00472 0.06418 0.07122 0 -0 0</pose>
        <geometry>
          <mesh>
            <scale>1 1 1</scale>
            <uri>model://robomaster_description/meshes/gimbal_left_armor.dae</uri>
          </mesh>
        </geometry>
      </visual>
      <visual name='gimbal_link_fixed_joint_lump__gimbal_right_armor_visual_2'>
        <pose>-0.00527 -0.06277 0.07314 0 -0 0</pose>
        <geometry>
          <mesh>
            <scale>1 1 1</scale>
            <uri>model://robomaster_description/meshes/gimbal_right_armor.dae</uri>
          </mesh>
        </geometry>
      </visual>
      <visual name='gimbal_link_fixed_joint_lump__gimbal_side_visual_3'>
        <pose>-0.00027 0.00034 0.08755 0 -0 0</pose>
        <geometry>
          <mesh>
            <scale>1 1 1</scale>
            <uri>model://robomaster_description/meshes/gimbal_side.dae</uri>
          </mesh>
        </geometry>
      </visual>
      <visual name='gimbal_link_fixed_joint_lump__gimbal_left_led_visual_4'>
        <pose>-0.02431 0.07079 0.10376 0 -0 0</pose>
        <geometry>
          <mesh>
            <scale>1 1 1</scale>
            <uri>model://robomaster_description/meshes/gimbal_left_led.dae</uri>
          </mesh>
        </geometry>
      </visual>
      <visual name='gimbal_link_fixed_joint_lump__gimbal_left_led_0_visual_5'>
        <pose>-0.02333 0.07079 0.07027 0 -0 0</pose>
        <geometry>
          <mesh>
            <scale>1 1 1</scale>
            <uri>model://robomaster_description/meshes/gimbal_left_led_0.dae</uri>
          </mesh>
        </geometry>
      </visual>
      <visual name='gimbal_link_fixed_joint_lump__gimbal_left_led_1_visual_6'>
        <pose>-0.00805 0.07079 0.05984 0 -0 0</pose>
        <geometry>
          <mesh>
            <scale>1 1 1</scale>
            <uri>model://robomaster_description/meshes/gimbal_left_led_1.dae</uri>
          </mesh>
        </geometry>
      </visual>
      <visual name='gimbal_link_fixed_joint_lump__gimbal_left_led_2_visual_7'>
        <pose>0.01059 0.07079 0.06074 0 -0 0</pose>
        <geometry>
          <mesh>
            <scale>1 1 1</scale>
            <uri>model://robomaster_description/meshes/gimbal_left_led_2.dae</uri>
          </mesh>
        </geometry>
      </visual>
      <visual name='gimbal_link_fixed_joint_lump__gimbal_left_led_3_visual_8'>
        <pose>0.0246 0.07079 0.0726 0 -0 0</pose>
        <geometry>
          <mesh>
            <scale>1 1 1</scale>
            <uri>model://robomaster_description/meshes/gimbal_left_led_3.dae</uri>
          </mesh>
        </geometry>
      </visual>
      <visual name='gimbal_link_fixed_joint_lump__gimbal_left_led_4_visual_9'>
        <pose>0.02321 0.07075 0.10433 0 -0 0</pose>
        <geometry>
          <mesh>
            <scale>1 1 1</scale>
            <uri>model://robomaster_description/meshes/gimbal_left_led_4.dae</uri>
          </mesh>
        </geometry>
      </visual>
      <visual name='gimbal_link_fixed_joint_lump__gimbal_left_led_5_visual_10'>
        <pose>0.00906 0.07079 0.11464 0 -0 0</pose>
        <geometry>
          <mesh>
            <scale>1 1 1</scale>
            <uri>model://robomaster_description/meshes/gimbal_left_led_5.dae</uri>
          </mesh>
        </geometry>
      </visual>
      <visual name='gimbal_link_fixed_joint_lump__gimbal_left_led_6_visual_11'>
        <pose>-0.00919 0.0708 0.1147 0 -0 0</pose>
        <geometry>
          <mesh>
            <scale>1 1 1</scale>
            <uri>model://robomaster_description/meshes/gimbal_left_led_6.dae</uri>
          </mesh>
        </geometry>
      </visual>
      <visual name='gimbal_link_fixed_joint_lump__gimbal_left_led_7_visual_12'>
        <pose>-0.02431 0.07079 0.10376 0 -0 0</pose>
        <geometry>
          <mesh>
            <scale>1 1 1</scale>
            <uri>model://robomaster_description/meshes/gimbal_left_led_7.dae</uri>
          </mesh>
        </geometry>
      </visual>
      <visual name='gimbal_link_fixed_joint_lump__gimbal_right_led_0_visual_13'>
        <pose>-0.02332 -0.0695 0.07027 0 -0 0</pose>
        <geometry>
          <mesh>
            <scale>1 1 1</scale>
            <uri>model://robomaster_description/meshes/gimbal_right_led_0.dae</uri>
          </mesh>
        </geometry>
      </visual>
      <visual name='gimbal_link_fixed_joint_lump__gimbal_right_led_1_visual_14'>
        <pose>-0.00805 -0.06952 0.05983 0 -0 0</pose>
        <geometry>
          <mesh>
            <scale>1 1 1</scale>
            <uri>model://robomaster_description/meshes/gimbal_right_led_1.dae</uri>
          </mesh>
        </geometry>
      </visual>
      <visual name='gimbal_link_fixed_joint_lump__gimbal_right_led_2_visual_15'>
        <pose>0.01059 -0.06952 0.06074 0 -0 0</pose>
        <geometry>
          <mesh>
            <scale>1 1 1</scale>
            <uri>model://robomaster_description/meshes/gimbal_right_led_2.dae</uri>
          </mesh>
        </geometry>
      </visual>
      <visual name='gimbal_link_fixed_joint_lump__gimbal_right_led_3_visual_16'>
        <pose>0.0246 -0.06952 0.0726 0 -0 0</pose>
        <geometry>
          <mesh>
            <scale>1 1 1</scale>
            <uri>model://robomaster_description/meshes/gimbal_right_led_3.dae</uri>
          </mesh>
        </geometry>
      </visual>
      <visual name='gimbal_link_fixed_joint_lump__gimbal_right_led_4_visual_17'>
        <pose>0.02322 -0.06924 0.10432 0 -0 0</pose>
        <geometry>
          <mesh>
            <scale>1 1 1</scale>
            <uri>model://robomaster_description/meshes/gimbal_right_led_4.dae</uri>
          </mesh>
        </geometry>
      </visual>
      <visual name='gimbal_link_fixed_joint_lump__gimbal_right_led_5_visual_18'>
        <pose>0.00906 -0.06933 0.1147 0 -0 0</pose>
        <geometry>
          <mesh>
            <scale>1 1 1</scale>
            <uri>model://robomaster_description/meshes/gimbal_right_led_5.dae</uri>
          </mesh>
        </geometry>
      </visual>
      <visual name='gimbal_link_fixed_joint_lump__gimbal_right_led_6_visual_19'>
        <pose>-0.00925 -0.06933 0.11467 0 -0 0</pose>
        <geometry>
          <mesh>
            <scale>1 1 1</scale>
            <uri>model://robomaster_description/meshes/gimbal_right_led_6.dae</uri>
          </mesh>
        </geometry>
      </visual>
      <visual name='gimbal_link_fixed_joint_lump__gimbal_right_led_7_visual_20'>
        <pose>-0.02431 -0.06933 0.10376 0 -0 0</pose>
        <geometry>
          <mesh>
            <scale>1 1 1</scale>
            <uri>model://robomaster_description/meshes/gimbal_right_led7.dae</uri>
          </mesh>
        </geometry>
      </visual>
    </link>
    <joint name='blaster_joint' type='revolute'>
      <pose relative_to='gimbal_link'>-0.00027 0.00034 0.08755 0 -0 0</pose>
      <parent>gimbal_link</parent>
      <child>blaster_link</child>
      <axis>
        <xyz>0 1 0</xyz>
        <limit>
          <lower>-0.5236</lower>
          <upper>0.4363</upper>
          <effort>0</effort>
          <velocity>0</velocity>
        </limit>
        <dynamics>
          <spring_reference>0</spring_reference>
          <spring_stiffness>0</spring_stiffness>
        </dynamics>
      </axis>
    </joint>
    <link name='blaster_link'>
      <pose relative_to='blaster_joint'>0 0 0 0 -0 0</pose>
      <inertial>
        <pose>0.00113 0.001318 0.007193 0 -0 0</pose>
        <mass>0.255</mass>
        <inertia>
          <ixx>0.00375502</ixx>
          <ixy>-1.14641e-06</ixy>
          <ixz>0.000147464</ixz>
          <iyy>0.00439585</iyy>
          <iyz>1.62371e-05</iyz>
          <izz>0.00370166</izz>
        </inertia>
      </inertial>
      <collision name='blaster_link_fixed_joint_lump__blaster_gun_collision_collision'>
        <pose>0.03675 0.00135 -0.01024 0 -0 0</pose>
        <geometry>
          <mesh>
            <scale>1 1 1</scale>
            <uri>model://robomaster_description/meshes/blaster_gun_collision.dae</uri>
          </mesh>
        </geometry>
      </collision>
      <collision name='blaster_link_fixed_joint_lump__blaster_magazin_collision_collision_1'>
        <pose>-0.02168 1e-05 0.02911 0 -0 0</pose>
        <geometry>
          <mesh>
            <scale>1 1 1</scale>
            <uri>model://robomaster_description/meshes/blaster_magazin_collision.dae</uri>
          </mesh>
        </geometry>
      </collision>
      <collision name='blaster_link_fixed_joint_lump__blaster_top_collision_collision_2'>
        <pose>0.00347 0.0008 0.01134 0 -0 0</pose>
        <geometry>
          <mesh>
            <scale>1 1 1</scale>
            <uri>model://robomaster_description/meshes/blaster_top_collision.dae</uri>
          </mesh>
        </geometry>
      </collision>
      <collision name='blaster_link_fixed_joint_lump__top_collision_3'>
        <pose>-0.003834 -2e-05 0.058616 0 -0 0</pose>
        <geometry>
          <box>
            <size>0.108973 0.059103 0.022915</size>
          </box>
        </geometry>
      </collision>
      <collision name='blaster_link_fixed_joint_lump__speaker_collision_collision_4'>
        <pose>-0.01709 0.00335 -0.06188 0 -0 0</pose>
        <geometry>
          <mesh>
            <scale>1 1 1</scale>
            <uri>model://robomaster_description/meshes/speaker_collision.dae</uri>
          </mesh>
        </geometry>
      </collision>
      <visual name='blaster_link_fixed_joint_lump__blaster_bug_visual'>
        <pose>0.00029 -0.03927 0.00764 0 -0 0</pose>
        <geometry>
          <mesh>
            <scale>0.7949 0.7949 0.7949</scale>
            <uri>model://robomaster_description/meshes/blaster_bug.dae</uri>
          </mesh>
        </geometry>
      </visual>
      <visual name='blaster_link_fixed_joint_lump__blaster_gun_visual_1'>
        <pose>0.03896 0.00326 -0.01071 0 -0 0</pose>
        <geometry>
          <mesh>
            <scale>1 1 1</scale>
            <uri>model://robomaster_description/meshes/blaster_gun.dae</uri>
          </mesh>
        </geometry>
      </visual>
      <visual name='blaster_link_fixed_joint_lump__blaster_magazin_visual_2'>
        <pose>-0.02031 1e-05 0.02866 0 -0 0</pose>
        <geometry>
          <mesh>
            <scale>1 1 1</scale>
            <uri>model://robomaster_description/meshes/blaster_magazin.dae</uri>
          </mesh>
        </geometry>
      </visual>
      <visual name='blaster_link_fixed_joint_lump__blaster_top_visual_3'>
        <pose>0.0014 0.00082 0.01703 0 -0 0</pose>
        <geometry>
          <mesh>
            <scale>1 1 1</scale>
            <uri>model://robomaster_description/meshes/blaster_top.dae</uri>
          </mesh>
        </geometry>
      </visual>
      <visual name='blaster_link_fixed_joint_lump__camera_visual_4'>
        <pose>0.072394 0 0.031429 0 -0.174529 0</pose>
        <geometry>
          <mesh>
            <scale>1 1 1</scale>
            <uri>model://robomaster_description/meshes/camera.dae</uri>
          </mesh>
        </geometry>
      </visual>
      <visual name='blaster_link_fixed_joint_lump__intelligent_controller_visual_5'>
        <pose>-0.027 0 0.060477 0 -0 0</pose>
        <geometry>
          <mesh>
            <scale>1 1 1</scale>
            <uri>model://robomaster_description/meshes/intelligent_controller.dae</uri>
          </mesh>
        </geometry>
      </visual>
      <visual name='blaster_link_fixed_joint_lump__wifi_antenna_left_visual_6'>
        <pose>-0.041711 0.034479 0.073287 0 -0 0</pose>
        <geometry>
          <mesh>
            <scale>1 1 1</scale>
            <uri>model://robomaster_description/meshes/wifi_antenna_left.dae</uri>
          </mesh>
        </geometry>
      </visual>
      <visual name='blaster_link_fixed_joint_lump__wifi_antenna_right_visual_7'>
        <pose>-0.041713 -0.03514 0.0742 0 -0 0</pose>
        <geometry>
          <mesh>
            <scale>1 1 1</scale>
            <uri>model://robomaster_description/meshes/wifi_antenna_right.dae</uri>
          </mesh>
        </geometry>
      </visual>
      <visual name='blaster_link_fixed_joint_lump__speaker_visual_8'>
        <pose>-0.01301 0.00691 -0.06117 0 -0 0</pose>
        <geometry>
          <mesh>
            <scale>1 1 1</scale>
            <uri>model://robomaster_description/meshes/speaker.dae</uri>
          </mesh>
        </geometry>
      </visual>
    </link>
  </model>
</sdf>
